Workbook

Sheet Sales Data
A1: Serial No | B1: Product Name | C1: Sale Price | D1: Sale Date | E1: Customer Name | F1: Month | G1: ProductID | H1: Sale Quantity | I1: Profit | J1: Revenue
A2: 1 | B2: 27-inch Monitor | C2: 16680 | D2: 45965 | E2: Neha Kapoor | F2: =TEXT(D2,"mmmm") -> November | G2: =INDEX('Product Summary'!$A$5:$A$24,MATCH(B2,'Product Summary'!$B$5:$B$24,0)) -> PRD-1011 | H2: 3 | I2: =ROUND(J2*INDEX('Product Summary'!$E$5:$E$24,MATCH(B2,'Product Summary'!$B$5:$B$24,0)),2) -> 7506 | J2: =C2*H2 -> 50040
A3: 2 | B3: Wireless Mouse | C3: 805 | D3: 45965 | E3: Neha Verma | F3: =TEXT(D3,"mmmm") -> November | G3: =INDEX('Product Summary'!$A$5:$A$24,MATCH(B3,'Product Summary'!$B$5:$B$24,0)) -> PRD-1001 | H3: 4 | I3: =ROUND(J3*INDEX('Product Summary'!$E$5:$E$24,MATCH(B3,'Product Summary'!$B$5:$B$24,0)),2) -> 1030.4 | J3: =C3*H3 -> 3220
A4: 3 | B4: Webcam Full HD | C4: 2885 | D4: 45966 | E4: Karan Gupta | F4: =TEXT(D4,"mmmm") -> November | G4: =INDEX('Product Summary'!$A$5:$A$24,MATCH(B4,'Product Summary'!$B$5:$B$24,0)) -> PRD-1005 | H4: 5 | I4: =ROUND(J4*INDEX('Product Summary'!$E$5:$E$24,MATCH(B4,'Product Summary'!$B$5:$B$24,0)),2) -> 3750.5 | J4: =C4*H4 -> 14425
A5: 4 | B5: 27-inch Monitor | C5: 16440 | D5: 45966 | E5: Rohan Menon | F5: =TEXT(D5,"mmmm") -> November | G5: =INDEX('Product Summary'!$A$5:$A$24,MATCH(B5,'Product Summary'!$B$5:$B$24,0)) -> PRD-1011 | H5: 3 | I5: =ROUND(J5*INDEX('Product Summary'!$E$5:$E$24,MATCH(B5,'Product Summary'!$B$5:$B$24,0)),2) -> 7398 | J5: =C5*H5 -> 49320
A6: 5 | B6: 27-inch Monitor | C6: 17645 | D6: 45967 | E6: Suresh Das | F6: =TEXT(D6,"mmmm") -> November | G6: =INDEX('Product Summary'!$A$5:$A$24,MATCH(B6,'Product Summary'!$B$5:$B$24,0)) -> PRD-1011 | H6: 1 | I6: =ROUND(J6*INDEX('Product Summary'!$E$5:$E$24,MATCH(B6,'Product Summary'!$B$5:$B$24,0)),2) -> 2646.75 | J6: =C6*H6 -> 17645
A7: 6 | B7: Laptop Backpack | C7: 1685 | D7: 45968 | E7: Riya Banerjee | F7: =TEXT(D7,"mmmm") -> November | G7: =INDEX('Product Summary'!$A$5:$A$24,MATCH(B7,'Product Summary'!$B$5:$B$24,0)) -> PRD-1003 | H7: 8 | I7: =ROUND(J7*INDEX('Product Summary'!$E$5:$E$24,MATCH(B7,'Product Summary'!$B$5:$B$24,0)),2) -> 4718 | J7: =C7*H7 -> 13480
A8: 7 | B8: Tablet 10-inch | C8: 19430 | D8: 45970 | E8: Sunita Reddy | F8: =TEXT(D8,"mmmm") -> November | G8: =INDEX('Product Summary'!$A$5:$A$24,MATCH(B8,'Product Summary'!$B$5:$B$24,0)) -> PRD-1019 | H8: 2 | I8: =ROUND(J8*INDEX('Product Summary'!$E$5:$E$24,MATCH(B8,'Product Summary'!$B$5:$B$24,0)),2) -> 4663.2 | J8: =C8*H8 -> 38860
A9: 8 | B9: Noise-Cancelling Headphones | C9: 7610 | D9: 45971 | E9: Karan Nair | F9: =TEXT(D9,"mmmm") -> November | G9: =INDEX('Product Summary'!$A$5:$A$24,MATCH(B9,'Product Summary'!$B$5:$B$24,0)) -> PRD-1008 | H9: 4 | I9: =ROUND(J9*INDEX('Product Summary'!$E$5:$E$24,MATCH(B9,'Product Summary'!$B$5:$B$24,0)),2) -> 7305.6 | J9: =C9*H9 -> 30440
A10: 9 | B10: Wireless Mouse | C10: 800 | D10: 45972 | E10: Sunita Chopra | F10: =TEXT(D10,"mmmm") -> November | G10: =INDEX('Product Summary'!$A$5:$A$24,MATCH(B10,'Product Summary'!$B$5:$B$24,0)) -> PRD-1001 | H10: 5 | I10: =ROUND(J10*INDEX('Product Summary'!$E$5:$E$24,MATCH(B10,'Product Summary'!$B$5:$B$24,0)),2) -> 1280 | J10: =C10*H10 -> 4000
A11: 10 | B11: Standing Desk | C11: 19320 | D11: 45973 | E11: Shreya Agarwal | F11: =TEXT(D11,"mmmm") -> November | G11: =INDEX('Product Summary'!$A$5:$A$24,MATCH(B11,'Product Summary'!$B$5:$B$24,0)) -> PRD-1016 | H11: 1 | I11: =ROUND(J11*INDEX('Product Summary'!$E$5:$E$24,MATCH(B11,'Product Summary'!$B$5:$B$24,0)),2) -> 3670.8 | J11: =C11*H11 -> 19320
A12: 11 | B12: USB-C Hub 7-in-1 | C12: 2140 | D12: 45973 | E12: Lakshmi Malhotra | F12: =TEXT(D12,"mmmm") -> November | G12: =INDEX('Product Summary'!$A$5:$A$24,MATCH(B12,'Product Summary'!$B$5:$B$24,0)) -> PRD-1004 | H12: 1 | I12: =ROUND(J12*INDEX('Product Summary'!$E$5:$E$24,MATCH(B12,'Product Summary'!$B$5:$B$24,0)),2) -> 642 | J12: =C12*H12 -> 2140
A13: 12 | B13: Air Purifier | C13: 10475 | D13: 45974 | E13: Rahul Chatterjee | F13: =TEXT(D13,"mmmm") -> November | G13: =INDEX('Product Summary'!$A$5:$A$24,MATCH(B13,'Product Summary'!$B$5:$B$24,0)) -> PRD-1018 | H13: 3 | I13: =ROUND(J13*INDEX('Product Summary'!$E$5:$E$24,MATCH(B13,'Product Summary'!$B$5:$B$24,0)),2) -> 6599.25 | J13: =C13*H13 -> 31425
... A501: 500 | B501: External SSD 1TB | C501: 8715 | D501: 46321 | E501: Tanvi Nair | F501: =TEXT(D501,"mmmm") -> October | G501: =INDEX('Product Summary'!$A$5:$A$24,MATCH(B501,'Product Summary'!$B$5:$B$24,0)) -> PRD-1012 | H501: 4 | I501: =ROUND(J501*INDEX('Product Summary'!$E$5:$E$24,MATCH(B501,'Product Summary'!$B$5:$B$24,0)),2) -> 6274.8 | J501: =C501*H501 -> 34860

Sheet Dashboard
B1: SALES & REVENUE ANALYSIS DASHBOARD | AB1: helper criteria
AB2: =IF($E$5="All Months","*",$E$5) -> *
B3: SYNTHETIC SAMPLE DATA | 500 transactions | Nov 2025 - Oct 2026 | All amounts in Indian Rupees (₹) | AB3: =IF($M$5="All Products","*",$M$5) -> *
B5: Filter by Month: | E5: All Months | J5: Filter by Product: | M5: All Products | U5: <- pick from the dropdowns
B7: TOTAL REVENUE | G7: TOTAL PROFIT | L7: TOTAL QUANTITY SOLD | Q7: TOTAL SALES TRANSACTIONS | V7: AVERAGE ORDER VALUE
B8: =SUMIFS('Sales Data'!$J:$J,'Sales Data'!$F:$F,$AB$2,'Sales Data'!$B:$B,$AB$3) -> 7970370 | G8: =SUMIFS('Sales Data'!$I:$I,'Sales Data'!$F:$F,$AB$2,'Sales Data'!$B:$B,$AB$3) -> 1652570.5 | L8: =SUMIFS('Sales Data'!$H:$H,'Sales Data'!$F:$F,$AB$2,'Sales Data'!$B:$B,$AB$3) -> 1715 | Q8: =COUNTIFS('Sales Data'!$A:$A,">0",'Sales Data'!$F:$F,$AB$2,'Sales Data'!$B:$B,$AB$3) -> 500 | V8: =IFERROR(B8/Q8,0) -> 15940.74
B72: Dashboard is formula-driven: it updates when Sales Data changes. Month filter drives KPIs + product charts; Product filter drives KPIs + monthly charts. See 'Read Me' for PivotTable/Slicer steps.

Sheet Monthly Summary
A1: MONTHLY SUMMARY
A2: ="Synthetic sample data (Nov 2025 - Oct 2026) | Product filter from Dashboard: "&Dashboard!$M$5&" (change it on the Dashboard sheet)" -> Synthetic sample data (Nov 2025 - Oct 2026) | Product filter from Dashboard: All Products (change it on the Dashboard sheet)
A4: Month | B4: Transactions | C4: Quantity Sold | D4: Revenue (₹) | E4: Profit (₹) | F4: Profit Margin % | G4: Avg Order Value (₹) | H4: Revenue Share %
A5: November | B5: =COUNTIFS('Sales Data'!$A:$A,">0",'Sales Data'!$F:$F,$A5,'Sales Data'!$B:$B,Dashboard!$AB$3) -> 45 | C5: =SUMIFS('Sales Data'!$H:$H,'Sales Data'!$F:$F,$A5,'Sales Data'!$B:$B,Dashboard!$AB$3) -> 152 | D5: =SUMIFS('Sales Data'!$J:$J,'Sales Data'!$F:$F,$A5,'Sales Data'!$B:$B,Dashboard!$AB$3) -> 783205 | E5: =SUMIFS('Sales Data'!$I:$I,'Sales Data'!$F:$F,$A5,'Sales Data'!$B:$B,Dashboard!$AB$3) -> 154284.6 | F5: =IFERROR(E5/D5,0) -> 0.19699134 | G5: =IFERROR(D5/B5,0) -> 17404.556 | H5: =IFERROR(D5/D$17,0) -> 0.098264572
A6: December | B6: =COUNTIFS('Sales Data'!$A:$A,">0",'Sales Data'!$F:$F,$A6,'Sales Data'!$B:$B,Dashboard!$AB$3) -> 34 | C6: =SUMIFS('Sales Data'!$H:$H,'Sales Data'!$F:$F,$A6,'Sales Data'!$B:$B,Dashboard!$AB$3) -> 109 | D6: =SUMIFS('Sales Data'!$J:$J,'Sales Data'!$F:$F,$A6,'Sales Data'!$B:$B,Dashboard!$AB$3) -> 481020 | E6: =SUMIFS('Sales Data'!$I:$I,'Sales Data'!$F:$F,$A6,'Sales Data'!$B:$B,Dashboard!$AB$3) -> 105710.1 | F6: =IFERROR(E6/D6,0) -> 0.21976238 | G6: =IFERROR(D6/B6,0) -> 14147.647 | H6: =IFERROR(D6/D$17,0) -> 0.060351025
A7: January | B7: =COUNTIFS('Sales Data'!$A:$A,">0",'Sales Data'!$F:$F,$A7,'Sales Data'!$B:$B,Dashboard!$AB$3) -> 41 | C7: =SUMIFS('Sales Data'!$H:$H,'Sales Data'!$F:$F,$A7,'Sales Data'!$B:$B,Dashboard!$AB$3) -> 152 | D7: =SUMIFS('Sales Data'!$J:$J,'Sales Data'!$F:$F,$A7,'Sales Data'!$B:$B,Dashboard!$AB$3) -> 572370 | E7: =SUMIFS('Sales Data'!$I:$I,'Sales Data'!$F:$F,$A7,'Sales Data'!$B:$B,Dashboard!$AB$3) -> 129073.35 | F7: =IFERROR(E7/D7,0) -> 0.22550684 | G7: =IFERROR(D7/B7,0) -> 13960.244 | H7: =IFERROR(D7/D$17,0) -> 0.071812225
A8: February | B8: =COUNTIFS('Sales Data'!$A:$A,">0",'Sales Data'!$F:$F,$A8,'Sales Data'!$B:$B,Dashboard!$AB$3) -> 40 | C8: =SUMIFS('Sales Data'!$H:$H,'Sales Data'!$F:$F,$A8,'Sales Data'!$B:$B,Dashboard!$AB$3) -> 130 | D8: =SUMIFS('Sales Data'!$J:$J,'Sales Data'!$F:$F,$A8,'Sales Data'!$B:$B,Dashboard!$AB$3) -> 628830 | E8: =SUMIFS('Sales Data'!$I:$I,'Sales Data'!$F:$F,$A8,'Sales Data'!$B:$B,Dashboard!$AB$3) -> 136316.15 | F8: =IFERROR(E8/D8,0) -> 0.21677743 | G8: =IFERROR(D8/B8,0) -> 15720.75 | H8: =IFERROR(D8/D$17,0) -> 0.078895961
A9: March | B9: =COUNTIFS('Sales Data'!$A:$A,">0",'Sales Data'!$F:$F,$A9,'Sales Data'!$B:$B,Dashboard!$AB$3) -> 32 | C9: =SUMIFS('Sales Data'!$H:$H,'Sales Data'!$F:$F,$A9,'Sales Data'!$B:$B,Dashboard!$AB$3) -> 114 | D9: =SUMIFS('Sales Data'!$J:$J,'Sales Data'!$F:$F,$A9,'Sales Data'!$B:$B,Dashboard!$AB$3) -> 466900 | E9: =SUMIFS('Sales Data'!$I:$I,'Sales Data'!$F:$F,$A9,'Sales Data'!$B:$B,Dashboard!$AB$3) -> 99532.15 | F9: =IFERROR(E9/D9,0) -> 0.21317659 | G9: =IFERROR(D9/B9,0) -> 14590.625 | H9: =IFERROR(D9/D$17,0) -> 0.058579464
A10: April | B10: =COUNTIFS('Sales Data'!$A:$A,">0",'Sales Data'!$F:$F,$A10,'Sales Data'!$B:$B,Dashboard!$AB$3) -> 33 | C10: =SUMIFS('Sales Data'!$H:$H,'Sales Data'!$F:$F,$A10,'Sales Data'!$B:$B,Dashboard!$AB$3) -> 127 | D10: =SUMIFS('Sales Data'!$J:$J,'Sales Data'!$F:$F,$A10,'Sales Data'!$B:$B,Dashboard!$AB$3) -> 554150 | E10: =SUMIFS('Sales Data'!$I:$I,'Sales Data'!$F:$F,$A10,'Sales Data'!$B:$B,Dashboard!$AB$3) -> 112469.9 | F10: =IFERROR(E10/D10,0) -> 0.20295931 | G10: =IFERROR(D10/B10,0) -> 16792.424 | H10: =IFERROR(D10/D$17,0) -> 0.069526258
A11: May | B11: =COUNTIFS('Sales Data'!$A:$A,">0",'Sales Data'!$F:$F,$A11,'Sales Data'!$B:$B,Dashboard!$AB$3) -> 48 | C11: =SUMIFS('Sales Data'!$H:$H,'Sales Data'!$F:$F,$A11,'Sales Data'!$B:$B,Dashboard!$AB$3) -> 170 | D11: =SUMIFS('Sales Data'!$J:$J,'Sales Data'!$F:$F,$A11,'Sales Data'!$B:$B,Dashboard!$AB$3) -> 827635 | E11: =SUMIFS('Sales Data'!$I:$I,'Sales Data'!$F:$F,$A11,'Sales Data'!$B:$B,Dashboard!$AB$3) -> 163684.4 | F11: =IFERROR(E11/D11,0) -> 0.19777366 | G11: =IFERROR(D11/B11,0) -> 17242.396 | H11: =IFERROR(D11/D$17,0) -> 0.10383897
A12: June | B12: =COUNTIFS('Sales Data'!$A:$A,">0",'Sales Data'!$F:$F,$A12,'Sales Data'!$B:$B,Dashboard!$AB$3) -> 37 | C12: =SUMIFS('Sales Data'!$H:$H,'Sales Data'!$F:$F,$A12,'Sales Data'!$B:$B,Dashboard!$AB$3) -> 147 | D12: =SUMIFS('Sales Data'!$J:$J,'Sales Data'!$F:$F,$A12,'Sales Data'!$B:$B,Dashboard!$AB$3) -> 577435 | E12: =SUMIFS('Sales Data'!$I:$I,'Sales Data'!$F:$F,$A12,'Sales Data'!$B:$B,Dashboard!$AB$3) -> 131575.95 | F12: =IFERROR(E12/D12,0) -> 0.22786279 | G12: =IFERROR(D12/B12,0) -> 15606.351 | H12: =IFERROR(D12/D$17,0) -> 0.072447703
A13: July | B13: =COUNTIFS('Sales Data'!$A:$A,">0",'Sales Data'!$F:$F,$A13,'Sales Data'!$B:$B,Dashboard!$AB$3) -> 44 | C13: =SUMIFS('Sales Data'!$H:$H,'Sales Data'!$F:$F,$A13,'Sales Data'!$B:$B,Dashboard!$AB$3) -> 147 | D13: =SUMIFS('Sales Data'!$J:$J,'Sales Data'!$F:$F,$A13,'Sales Data'!$B:$B,Dashboard!$AB$3) -> 704620 | E13: =SUMIFS('Sales Data'!$I:$I,'Sales Data'!$F:$F,$A13,'Sales Data'!$B:$B,Dashboard!$AB$3) -> 136582.7 | F13: =IFERROR(E13/D13,0) -> 0.19383881 | G13: =IFERROR(D13/B13,0) -> 16014.091 | H13: =IFERROR(D13/D$17,0) -> 0.08840493
A14: August | B14: =COUNTIFS('Sales Data'!$A:$A,">0",'Sales Data'!$F:$F,$A14,'Sales Data'!$B:$B,Dashboard!$AB$3) -> 51 | C14: =SUMIFS('Sales Data'!$H:$H,'Sales Data'!$F:$F,$A14,'Sales Data'!$B:$B,Dashboard!$AB$3) -> 176 | D14: =SUMIFS('Sales Data'!$J:$J,'Sales Data'!$F:$F,$A14,'Sales Data'!$B:$B,Dashboard!$AB$3) -> 759855 | E14: =SUMIFS('Sales Data'!$I:$I,'Sales Data'!$F:$F,$A14,'Sales Data'!$B:$B,Dashboard!$AB$3) -> 162907.15 | F14: =IFERROR(E14/D14,0) -> 0.21439242 | G14: =IFERROR(D14/B14,0) -> 14899.118 | H14: =IFERROR(D14/D$17,0) -> 0.095334972
A15: September | B15: =COUNTIFS('Sales Data'!$A:$A,">0",'Sales Data'!$F:$F,$A15,'Sales Data'!$B:$B,Dashboard!$AB$3) -> 44 | C15: =SUMIFS('Sales Data'!$H:$H,'Sales Data'!$F:$F,$A15,'Sales Data'!$B:$B,Dashboard!$AB$3) -> 120 | D15: =SUMIFS('Sales Data'!$J:$J,'Sales Data'!$F:$F,$A15,'Sales Data'!$B:$B,Dashboard!$AB$3) -> 791015 | E15: =SUMIFS('Sales Data'!$I:$I,'Sales Data'!$F:$F,$A15,'Sales Data'!$B:$B,Dashboard!$AB$3) -> 150894.5 | F15: =IFERROR(E15/D15,0) -> 0.19076061 | G15: =IFERROR(D15/B15,0) -> 17977.614 | H15: =IFERROR(D15/D$17,0) -> 0.099244452
A16: October | B16: =COUNTIFS('Sales Data'!$A:$A,">0",'Sales Data'!$F:$F,$A16,'Sales Data'!$B:$B,Dashboard!$AB$3) -> 51 | C16: =SUMIFS('Sales Data'!$H:$H,'Sales Data'!$F:$F,$A16,'Sales Data'!$B:$B,Dashboard!$AB$3) -> 171 | D16: =SUMIFS('Sales Data'!$J:$J,'Sales Data'!$F:$F,$A16,'Sales Data'!$B:$B,Dashboard!$AB$3) -> 823335 | E16: =SUMIFS('Sales Data'!$I:$I,'Sales Data'!$F:$F,$A16,'Sales Data'!$B:$B,Dashboard!$AB$3) -> 169539.55 | F16: =IFERROR(E16/D16,0) -> 0.20591806 | G16: =IFERROR(D16/B16,0) -> 16143.824 | H16: =IFERROR(D16/D$17,0) -> 0.10329947
A17: TOTAL | B17: =SUM(B5:B16) -> 500 | C17: =SUM(C5:C16) -> 1715 | D17: =SUM(D5:D16) -> 7970370 | E17: =SUM(E5:E16) -> 1652570.5 | F17: =IFERROR(E17/D17,0) -> 0.20733925 | G17: =IFERROR(D17/B17,0) -> 15940.74 | H17: =SUM(H5:H16) -> 1

Sheet Product Summary
A1: PRODUCT SUMMARY
A2: ="Synthetic sample data | Month filter from Dashboard: "&Dashboard!$E$5&" (change it on the Dashboard sheet)" -> Synthetic sample data | Month filter from Dashboard: All Months (change it on the Dashboard sheet)
M3: RANKED BY REVENUE (feeds Top 10 and product charts)
A4: Product ID | B4: Product Name | C4: Category | D4: List Price (₹) | E4: Assumed Profit Margin % | F4: Transactions | G4: Quantity Sold | H4: Revenue (₹) | I4: Profit (₹) | J4: Actual Profit Margin % | K4: Revenue Rank | M4: Rank | N4: Product (ranked by revenue) | O4: Revenue (₹) | P4: Profit (₹) | Q4: Quantity Sold | S4: Product list (dropdown source)
A5: PRD-1001 | B5: Wireless Mouse | C5: Accessories | D5: 799 | E5: 0.32 | F5: =COUNTIFS('Sales Data'!$A:$A,">0",'Sales Data'!$B:$B,$B5,'Sales Data'!$F:$F,Dashboard!$AB$2) -> 48 | G5: =SUMIFS('Sales Data'!$H:$H,'Sales Data'!$B:$B,$B5,'Sales Data'!$F:$F,Dashboard!$AB$2) -> 250 | H5: =SUMIFS('Sales Data'!$J:$J,'Sales Data'!$B:$B,$B5,'Sales Data'!$F:$F,Dashboard!$AB$2) -> 198040 | I5: =SUMIFS('Sales Data'!$I:$I,'Sales Data'!$B:$B,$B5,'Sales Data'!$F:$F,Dashboard!$AB$2) -> 63372.8 | J5: =IFERROR(I5/H5,0) -> 0.32 | K5: =RANK(H5,$H$5:$H$24)+COUNTIF($H$5:H5,H5)-1 -> 18 | M5: 1 | N5: =INDEX($B$5:$B$24,MATCH($M5,$K$5:$K$24,0)) -> Smartphone 5G | O5: =INDEX($H$5:$H$24,MATCH($M5,$K$5:$K$24,0)) -> 1277725 | P5: =INDEX($I$5:$I$24,MATCH($M5,$K$5:$K$24,0)) -> 127772.5 | Q5: =INDEX($G$5:$G$24,MATCH($M5,$K$5:$K$24,0)) -> 52 | S5: All Products
A6: PRD-1002 | B6: Mechanical Keyboard | C6: Accessories | D6: 3499 | E6: 0.28 | F6: =COUNTIFS('Sales Data'!$A:$A,">0",'Sales Data'!$B:$B,$B6,'Sales Data'!$F:$F,Dashboard!$AB$2) -> 37 | G6: =SUMIFS('Sales Data'!$H:$H,'Sales Data'!$B:$B,$B6,'Sales Data'!$F:$F,Dashboard!$AB$2) -> 121 | H6: =SUMIFS('Sales Data'!$J:$J,'Sales Data'!$B:$B,$B6,'Sales Data'!$F:$F,Dashboard!$AB$2) -> 414900 | I6: =SUMIFS('Sales Data'!$I:$I,'Sales Data'!$B:$B,$B6,'Sales Data'!$F:$F,Dashboard!$AB$2) -> 116172 | J6: =IFERROR(I6/H6,0) -> 0.28 | K6: =RANK(H6,$H$5:$H$24)+COUNTIF($H$5:H6,H6)-1 -> 8 | M6: 2 | N6: =INDEX($B$5:$B$24,MATCH($M6,$K$5:$K$24,0)) -> 27-inch Monitor | O6: =INDEX($H$5:$H$24,MATCH($M6,$K$5:$K$24,0)) -> 601865 | P6: =INDEX($I$5:$I$24,MATCH($M6,$K$5:$K$24,0)) -> 90279.75 | Q6: =INDEX($G$5:$G$24,MATCH($M6,$K$5:$K$24,0)) -> 36 | S6: =B5 -> Wireless Mouse
A7: PRD-1003 | B7: Laptop Backpack | C7: Accessories | D7: 1799 | E7: 0.35 | F7: =COUNTIFS('Sales Data'!$A:$A,">0",'Sales Data'!$B:$B,$B7,'Sales Data'!$F:$F,Dashboard!$AB$2) -> 36 | G7: =SUMIFS('Sales Data'!$H:$H,'Sales Data'!$B:$B,$B7,'Sales Data'!$F:$F,Dashboard!$AB$2) -> 162 | H7: =SUMIFS('Sales Data'!$J:$J,'Sales Data'!$B:$B,$B7,'Sales Data'!$F:$F,Dashboard!$AB$2) -> 285110 | I7: =SUMIFS('Sales Data'!$I:$I,'Sales Data'!$B:$B,$B7,'Sales Data'!$F:$F,Dashboard!$AB$2) -> 99788.5 | J7: =IFERROR(I7/H7,0) -> 0.35 | K7: =RANK(H7,$H$5:$H$24)+COUNTIF($H$5:H7,H7)-1 -> 13 | M7: 3 | N7: =INDEX($B$5:$B$24,MATCH($M7,$K$5:$K$24,0)) -> Noise-Cancelling Headphones | O7: =INDEX($H$5:$H$24,MATCH($M7,$K$5:$K$24,0)) -> 600900 | P7: =INDEX($I$5:$I$24,MATCH($M7,$K$5:$K$24,0)) -> 144216 | Q7: =INDEX($G$5:$G$24,MATCH($M7,$K$5:$K$24,0)) -> 76 | S7: =B6 -> Mechanical Keyboard
A8: PRD-1004 | B8: USB-C Hub 7-in-1 | C8: Accessories | D8: 2299 | E8: 0.3 | F8: =COUNTIFS('Sales Data'!$A:$A,">0",'Sales Data'!$B:$B,$B8,'Sales Data'!$F:$F,Dashboard!$AB$2) -> 24 | G8: =SUMIFS('Sales Data'!$H:$H,'Sales Data'!$B:$B,$B8,'Sales Data'!$F:$F,Dashboard!$AB$2) -> 88 | H8: =SUMIFS('Sales Data'!$J:$J,'Sales Data'!$B:$B,$B8,'Sales Data'!$F:$F,Dashboard!$AB$2) -> 199305 | I8: =SUMIFS('Sales Data'!$I:$I,'Sales Data'!$B:$B,$B8,'Sales Data'!$F:$F,Dashboard!$AB$2) -> 59791.5 | J8: =IFERROR(I8/H8,0) -> 0.3 | K8: =RANK(H8,$H$5:$H$24)+COUNTIF($H$5:H8,H8)-1 -> 16 | M8: 4 | N8: =INDEX($B$5:$B$24,MATCH($M8,$K$5:$K$24,0)) -> Smart Watch | O8: =INDEX($H$5:$H$24,MATCH($M8,$K$5:$K$24,0)) -> 555090 | P8: =INDEX($I$5:$I$24,MATCH($M8,$K$5:$K$24,0)) -> 122119.8 | Q8: =INDEX($G$5:$G$24,MATCH($M8,$K$5:$K$24,0)) -> 94 | S8: =B7 -> Laptop Backpack
A9: PRD-1005 | B9: Webcam Full HD | C9: Accessories | D9: 2999 | E9: 0.26 | F9: =COUNTIFS('Sales Data'!$A:$A,">0",'Sales Data'!$B:$B,$B9,'Sales Data'!$F:$F,Dashboard!$AB$2) -> 24 | G9: =SUMIFS('Sales Data'!$H:$H,'Sales Data'!$B:$B,$B9,'Sales Data'!$F:$F,Dashboard!$AB$2) -> 84 | H9: =SUMIFS('Sales Data'!$J:$J,'Sales Data'!$B:$B,$B9,'Sales Data'!$F:$F,Dashboard!$AB$2) -> 247085 | I9: =SUMIFS('Sales Data'!$I:$I,'Sales Data'!$B:$B,$B9,'Sales Data'!$F:$F,Dashboard!$AB$2) -> 64242.1 | J9: =IFERROR(I9/H9,0) -> 0.26 | K9: =RANK(H9,$H$5:$H$24)+COUNTIF($H$5:H9,H9)-1 -> 15 | M9: 5 | N9: =INDEX($B$5:$B$24,MATCH($M9,$K$5:$K$24,0)) -> Ergonomic Office Chair | O9: =INDEX($H$5:$H$24,MATCH($M9,$K$5:$K$24,0)) -> 486925 | P9: =INDEX($I$5:$I$24,MATCH($M9,$K$5:$K$24,0)) -> 97385 | Q9: =INDEX($G$5:$G$24,MATCH($M9,$K$5:$K$24,0)) -> 42 | S9: =B8 -> USB-C Hub 7-in-1
A10: PRD-1006 | B10: Power Bank 20000mAh | C10: Mobile Accessories | D10: 1999 | E10: 0.27 | F10: =COUNTIFS('Sales Data'!$A:$A,">0",'Sales Data'!$B:$B,$B10,'Sales Data'!$F:$F,Dashboard!$AB$2) -> 31 | G10: =SUMIFS('Sales Data'!$H:$H,'Sales Data'!$B:$B,$B10,'Sales Data'!$F:$F,Dashboard!$AB$2) -> 173 | H10: =SUMIFS('Sales Data'!$J:$J,'Sales Data'!$B:$B,$B10,'Sales Data'!$F:$F,Dashboard!$AB$2) -> 339755 | I10: =SUMIFS('Sales Data'!$I:$I,'Sales Data'!$B:$B,$B10,'Sales Data'!$F:$F,Dashboard!$AB$2) -> 91733.85 | J10: =IFERROR(I10/H10,0) -> 0.27 | K10: =RANK(H10,$H$5:$H$24)+COUNTIF($H$5:H10,H10)-1 -> 11 | M10: 6 | N10: =INDEX($B$5:$B$24,MATCH($M10,$K$5:$K$24,0)) -> Tablet 10-inch | O10: =INDEX($H$5:$H$24,MATCH($M10,$K$5:$K$24,0)) -> 458970 | P10: =INDEX($I$5:$I$24,MATCH($M10,$K$5:$K$24,0)) -> 55076.4 | Q10: =INDEX($G$5:$G$24,MATCH($M10,$K$5:$K$24,0)) -> 23 | S10: =B9 -> Webcam Full HD
A11: PRD-1007 | B11: Bluetooth Speaker | C11: Audio | D11: 2999 | E11: 0.29 | F11: =COUNTIFS('Sales Data'!$A:$A,">0",'Sales Data'!$B:$B,$B11,'Sales Data'!$F:$F,Dashboard!$AB$2) -> 41 | G11: =SUMIFS('Sales Data'!$H:$H,'Sales Data'!$B:$B,$B11,'Sales Data'!$F:$F,Dashboard!$AB$2) -> 132 | H11: =SUMIFS('Sales Data'!$J:$J,'Sales Data'!$B:$B,$B11,'Sales Data'!$F:$F,Dashboard!$AB$2) -> 386385 | I11: =SUMIFS('Sales Data'!$I:$I,'Sales Data'!$B:$B,$B11,'Sales Data'!$F:$F,Dashboard!$AB$2) -> 112051.65 | J11: =IFERROR(I11/H11,0) -> 0.29 | K11: =RANK(H11,$H$5:$H$24)+COUNTIF($H$5:H11,H11)-1 -> 9 | M11: 7 | N11: =INDEX($B$5:$B$24,MATCH($M11,$K$5:$K$24,0)) -> External SSD 1TB | O11: =INDEX($H$5:$H$24,MATCH($M11,$K$5:$K$24,0)) -> 429325 | P11: =INDEX($I$5:$I$24,MATCH($M11,$K$5:$K$24,0)) -> 77278.5 | Q11: =INDEX($G$5:$G$24,MATCH($M11,$K$5:$K$24,0)) -> 51 | S11: =B10 -> Power Bank 20000mAh
A12: PRD-1008 | B12: Noise-Cancelling Headphones | C12: Audio | D12: 7999 | E12: 0.24 | F12: =COUNTIFS('Sales Data'!$A:$A,">0",'Sales Data'!$B:$B,$B12,'Sales Data'!$F:$F,Dashboard!$AB$2) -> 29 | G12: =SUMIFS('Sales Data'!$H:$H,'Sales Data'!$B:$B,$B12,'Sales Data'!$F:$F,Dashboard!$AB$2) -> 76 | H12: =SUMIFS('Sales Data'!$J:$J,'Sales Data'!$B:$B,$B12,'Sales Data'!$F:$F,Dashboard!$AB$2) -> 600900 | I12: =SUMIFS('Sales Data'!$I:$I,'Sales Data'!$B:$B,$B12,'Sales Data'!$F:$F,Dashboard!$AB$2) -> 144216 | J12: =IFERROR(I12/H12,0) -> 0.24 | K12: =RANK(H12,$H$5:$H$24)+COUNTIF($H$5:H12,H12)-1 -> 3 | M12: 8 | N12: =INDEX($B$5:$B$24,MATCH($M12,$K$5:$K$24,0)) -> Mechanical Keyboard | O12: =INDEX($H$5:$H$24,MATCH($M12,$K$5:$K$24,0)) -> 414900 | P12: =INDEX($I$5:$I$24,MATCH($M12,$K$5:$K$24,0)) -> 116172 | Q12: =INDEX($G$5:$G$24,MATCH($M12,$K$5:$K$24,0)) -> 121 | S12: =B11 -> Bluetooth Speaker
A13: PRD-1009 | B13: Smart Watch | C13: Wearables | D13: 5999 | E13: 0.22 | F13: =COUNTIFS('Sales Data'!$A:$A,">0",'Sales Data'!$B:$B,$B13,'Sales Data'!$F:$F,Dashboard!$AB$2) -> 31 | G13: =SUMIFS('Sales Data'!$H:$H,'Sales Data'!$B:$B,$B13,'Sales Data'!$F:$F,Dashboard!$AB$2) -> 94 | H13: =SUMIFS('Sales Data'!$J:$J,'Sales Data'!$B:$B,$B13,'Sales Data'!$F:$F,Dashboard!$AB$2) -> 555090 | I13: =SUMIFS('Sales Data'!$I:$I,'Sales Data'!$B:$B,$B13,'Sales Data'!$F:$F,Dashboard!$AB$2) -> 122119.8 | J13: =IFERROR(I13/H13,0) -> 0.22 | K13: =RANK(H13,$H$5:$H$24)+COUNTIF($H$5:H13,H13)-1 -> 4 | M13: 9 | N13: =INDEX($B$5:$B$24,MATCH($M13,$K$5:$K$24,0)) -> Bluetooth Speaker | O13: =INDEX($H$5:$H$24,MATCH($M13,$K$5:$K$24,0)) -> 386385 | P13: =INDEX($I$5:$I$24,MATCH($M13,$K$5:$K$24,0)) -> 112051.65 | Q13: =INDEX($G$5:$G$24,MATCH($M13,$K$5:$K$24,0)) -> 132 | S13: =B12 -> Noise-Cancelling Headphones
A14: PRD-1010 | B14: Fitness Band | C14: Wearables | D14: 2499 | E14: 0.25 | F14: =COUNTIFS('Sales Data'!$A:$A,">0",'Sales Data'!$B:$B,$B14,'Sales Data'!$F:$F,Dashboard!$AB$2) -> 24 | G14: =SUMIFS('Sales Data'!$H:$H,'Sales Data'!$B:$B,$B14,'Sales Data'!$F:$F,Dashboard!$AB$2) -> 74 | H14: =SUMIFS('Sales Data'!$J:$J,'Sales Data'!$B:$B,$B14,'Sales Data'!$F:$F,Dashboard!$AB$2) -> 182220 | I14: =SUMIFS('Sales Data'!$I:$I,'Sales Data'!$B:$B,$B14,'Sales Data'!$F:$F,Dashboard!$AB$2) -> 45555 | J14: =IFERROR(I14/H14,0) -> 0.25 | K14: =RANK(H14,$H$5:$H$24)+COUNTIF($H$5:H14,H14)-1 -> 19 | M14: 10 | N14: =INDEX($B$5:$B$24,MATCH($M14,$K$5:$K$24,0)) -> Laser Printer | O14: =INDEX($H$5:$H$24,MATCH($M14,$K$5:$K$24,0)) -> 340640 | P14: =INDEX($I$5:$I$24,MATCH($M14,$K$5:$K$24,0)) -> 54502.4 | Q14: =INDEX($G$5:$G$24,MATCH($M14,$K$5:$K$24,0)) -> 27 | S14: =B13 -> Smart Watch
A15: PRD-1011 | B15: 27-inch Monitor | C15: Computing | D15: 16999 | E15: 0.15 | F15: =COUNTIFS('Sales Data'!$A:$A,">0",'Sales Data'!$B:$B,$B15,'Sales Data'!$F:$F,Dashboard!$AB$2) -> 21 | G15: =SUMIFS('Sales Data'!$H:$H,'Sales Data'!$B:$B,$B15,'Sales Data'!$F:$F,Dashboard!$AB$2) -> 36 | H15: =SUMIFS('Sales Data'!$J:$J,'Sales Data'!$B:$B,$B15,'Sales Data'!$F:$F,Dashboard!$AB$2) -> 601865 | I15: =SUMIFS('Sales Data'!$I:$I,'Sales Data'!$B:$B,$B15,'Sales Data'!$F:$F,Dashboard!$AB$2) -> 90279.75 | J15: =IFERROR(I15/H15,0) -> 0.15 | K15: =RANK(H15,$H$5:$H$24)+COUNTIF($H$5:H15,H15)-1 -> 2 | M15: 11 | N15: =INDEX($B$5:$B$24,MATCH($M15,$K$5:$K$24,0)) -> Power Bank 20000mAh | O15: =INDEX($H$5:$H$24,MATCH($M15,$K$5:$K$24,0)) -> 339755 | P15: =INDEX($I$5:$I$24,MATCH($M15,$K$5:$K$24,0)) -> 91733.85 | Q15: =INDEX($G$5:$G$24,MATCH($M15,$K$5:$K$24,0)) -> 173 | S15: =B14 -> Fitness Band
A16: PRD-1012 | B16: External SSD 1TB | C16: Computing | D16: 8499 | E16: 0.18 | F16: =COUNTIFS('Sales Data'!$A:$A,">0",'Sales Data'!$B:$B,$B16,'Sales Data'!$F:$F,Dashboard!$AB$2) -> 17 | G16: =SUMIFS('Sales Data'!$H:$H,'Sales Data'!$B:$B,$B16,'Sales Data'!$F:$F,Dashboard!$AB$2) -> 51 | H16: =SUMIFS('Sales Data'!$J:$J,'Sales Data'!$B:$B,$B16,'Sales Data'!$F:$F,Dashboard!$AB$2) -> 429325 | I16: =SUMIFS('Sales Data'!$I:$I,'Sales Data'!$B:$B,$B16,'Sales Data'!$F:$F,Dashboard!$AB$2) -> 77278.5 | J16: =IFERROR(I16/H16,0) -> 0.18 | K16: =RANK(H16,$H$5:$H$24)+COUNTIF($H$5:H16,H16)-1 -> 7 | M16: 12 | N16: =INDEX($B$5:$B$24,MATCH($M16,$K$5:$K$24,0)) -> Standing Desk | O16: =INDEX($H$5:$H$24,MATCH($M16,$K$5:$K$24,0)) -> 339210 | P16: =INDEX($I$5:$I$24,MATCH($M16,$K$5:$K$24,0)) -> 64449.9 | Q16: =INDEX($G$5:$G$24,MATCH($M16,$K$5:$K$24,0)) -> 18 | S16: =B15 -> 27-inch Monitor
A17: PRD-1013 | B17: Wi-Fi 6 Router | C17: Networking | D17: 3999 | E17: 0.24 | F17: =COUNTIFS('Sales Data'!$A:$A,">0",'Sales Data'!$B:$B,$B17,'Sales Data'!$F:$F,Dashboard!$AB$2) -> 21 | G17: =SUMIFS('Sales Data'!$H:$H,'Sales Data'!$B:$B,$B17,'Sales Data'!$F:$F,Dashboard!$AB$2) -> 68 | H17: =SUMIFS('Sales Data'!$J:$J,'Sales Data'!$B:$B,$B17,'Sales Data'!$F:$F,Dashboard!$AB$2) -> 268770 | I17: =SUMIFS('Sales Data'!$I:$I,'Sales Data'!$B:$B,$B17,'Sales Data'!$F:$F,Dashboard!$AB$2) -> 64504.8 | J17: =IFERROR(I17/H17,0) -> 0.24 | K17: =RANK(H17,$H$5:$H$24)+COUNTIF($H$5:H17,H17)-1 -> 14 | M17: 13 | N17: =INDEX($B$5:$B$24,MATCH($M17,$K$5:$K$24,0)) -> Laptop Backpack | O17: =INDEX($H$5:$H$24,MATCH($M17,$K$5:$K$24,0)) -> 285110 | P17: =INDEX($I$5:$I$24,MATCH($M17,$K$5:$K$24,0)) -> 99788.5 | Q17: =INDEX($G$5:$G$24,MATCH($M17,$K$5:$K$24,0)) -> 162 | S17: =B16 -> External SSD 1TB
... A24: PRD-1020 | B24: Smartphone 5G | C24: Mobiles & Tablets | D24: 24999 | E24: 0.1 | F24: =COUNTIFS('Sales Data'!$A:$A,">0",'Sales Data'!$B:$B,$B24,'Sales Data'!$F:$F,Dashboard!$AB$2) -> 25 | G24: =SUMIFS('Sales Data'!$H:$H,'Sales Data'!$B:$B,$B24,'Sales Data'!$F:$F,Dashboard!$AB$2) -> 52 | H24: =SUMIFS('Sales Data'!$J:$J,'Sales Data'!$B:$B,$B24,'Sales Data'!$F:$F,Dashboard!$AB$2) -> 1277725 | I24: =SUMIFS('Sales Data'!$I:$I,'Sales Data'!$B:$B,$B24,'Sales Data'!$F:$F,Dashboard!$AB$2) -> 127772.5 | J24: =IFERROR(I24/H24,0) -> 0.1 | K24: =RANK(H24,$H$5:$H$24)+COUNTIF($H$5:H24,H24)-1 -> 1 | M24: 20 | N24: =INDEX($B$5:$B$24,MATCH($M24,$K$5:$K$24,0)) -> LED Desk Lamp | O24: =INDEX($H$5:$H$24,MATCH($M24,$K$5:$K$24,0)) -> 159215 | P24: =INDEX($I$5:$I$24,MATCH($M24,$K$5:$K$24,0)) -> 60501.7 | Q24: =INDEX($G$5:$G$24,MATCH($M24,$K$5:$K$24,0)) -> 124 | S24: =B23 -> Tablet 10-inch
B25: TOTAL | F25: =SUM(F5:F24) -> 500 | G25: =SUM(G5:G24) -> 1715 | H25: =SUM(H5:H24) -> 7970370 | I25: =SUM(I5:I24) -> 1652570.5 | J25: =IFERROR(I25/H25,0) -> 0.20733925 | S25: =B24 -> Smartphone 5G
A27: Blue cells (column E) are the assumed profit-margin inputs; the Sales Data 'Profit' column reads them. To add a product, insert a row inside this block and extend the ranges.

Sheet Read Me
A1: SALES & REVENUE ANALYSIS DASHBOARD - READ ME
A2: ALL DATA IN THIS WORKBOOK IS SYNTHETIC SAMPLE DATA generated for a portfolio project. Names, prices, sales and margins are fictional and do not represent any real business or person.
A4: 1. PROJECT OVERVIEW
A5: Purpose | B5: Analyse 12 months of sales (Nov 2025 - Oct 2026) to track revenue, profit, quantity and product performance, and present them in one interactive dashboard.
A6: Tools / skills shown | B6: Excel Tables, structured data entry, INDEX/MATCH, SUMIFS/COUNTIFS, RANK, data validation (dropdown filters), conditional formatting (data bars), KPI cards, combo charts, documentation.
A8: 2. WORKSHEETS
A9: Sales Data | B9: 500 transaction rows in the Excel Table 'SalesTable' (filters on, header row frozen).
A10: Dashboard | B10: KPI cards, 2 dropdown filters and 6 charts. Everything is formula-driven.
A11: Monthly Summary | B11: Transactions, quantity, revenue, profit, margin %, average order value and revenue share for each month.
A12: Product Summary | B12: Product catalogue + assumed margins (inputs), product totals, and a ranked-by-revenue table that feeds the Top 10 and product charts.
A13: Read Me | B13: This page.
A15: 3. COLUMN DICTIONARY (Sales Data)
A16: Serial No | B16: Hard-coded 1 to 500.
A17: Product Name | B17: Hard-coded; one of 20 products listed on Product Summary.
A18: Sale Price | B18: Hard-coded unit price in ₹ (list price varied by roughly -8% to +5% to mimic discounts / price changes).
A19: Sale Date | B19: Hard-coded real Excel dates, 01-Nov-2025 to 26-Oct-2026.
A20: Customer Name | B20: Hard-coded synthetic Indian names (110 distinct customers, repeat purchases allowed).
A21: Month | B21: Formula: TEXT(SaleDate,"mmmm") - derived automatically from Sale Date.
A22: ProductID | B22: Formula: INDEX / MATCH on the Product Summary catalogue (PRD-1001 to PRD-1020, one unique ID per product).
A23: Sale Quantity | B23: Hard-coded units sold (1 to 10 for low-priced items, 1 to 2-3 for high-priced items).
A24: Profit | B24: Formula: ROUND(Revenue x Assumed Profit Margin %, 2); margin is looked up per product (see assumption below).
A25: Revenue | B25: Formula: Sale Price x Sale Quantity.
A27: 4. ASSUMPTIONS
A28: Profit margin | B28: Profit = Revenue x product margin. Margins are ASSUMED (not real) and set per product on Product Summary, column E (blue = editable input): 10%-20% for big-ticket items (phones, tablets, monitors, furniture), 24%-38% for accessories and small items. Change a blue cell and the whole workbook updates.
A29: Currency | B29: All amounts are in Indian Rupees (₹). Large totals use Indian digit grouping (lakh / crore).
A30: Seasonality | B30: More sales were generated for Oct-Dec (festive season) than for Jun-Jul to make the trend charts realistic.
A31: Average Order Value | B31: Total Revenue / Number of transactions (each row = one order).
A32: Month names | B32: Month is shown as a month name. This is unambiguous because the data spans exactly 12 months. If you extend beyond 12 months, change Month to a 'yyyy-mm' text and update the month labels.
A34: 5. HOW TO USE THE DASHBOARD
A35: Dropdown filters | B35: On Dashboard, use 'Filter by Month' and 'Filter by Product' (yellow cells). Month filter drives the KPIs and the product charts/tables; Product filter drives the KPIs and the monthly charts/tables. Set both back to 'All ...' for full totals.
A36: Refreshing data | B36: Type or paste new rows directly under the last row of Sales Data (the Table expands). Copy the formulas in Month, ProductID, Profit and Revenue down. All summaries use whole-column references, so they pick up new rows automatically.
A37: Adding months / products | B37: Add a month label or product row to the summary sheets (the Product Summary and Monthly Summary lists are typed in).
A39: 6. OPTIONAL: ADD POWERTABLES (PivotTables, PivotCharts, Slicers)
A40: Why optional | B40: PivotTables and slicers are created inside desktop Excel and cannot be embedded by the script that generated this file. The dashboard above already provides the same views using formulas + dropdown filters. Follow the steps below if you want true slicers.
A41: Step 1 - PivotTable | B41: Click any cell in Sales Data > Insert > PivotTable > New Worksheet. Put 'Month' in Rows, and 'Revenue', 'Profit', 'Sale Quantity' in Values (Sum).
A42: Step 2 - PivotChart | B42: Click the PivotTable > Insert > PivotChart > choose Line (revenue by month) or Column / Bar.
A43: Step 3 - Slicers | B43: Click the PivotTable > PivotTable Analyze > Insert Slicer > tick 'Month' and 'Product Name'. Right-click each slicer > Report Connections to link it to every PivotTable.
A44: Step 4 - Refresh | B44: Data > Refresh All after changing source data (PivotTables do not auto-refresh unless set in PivotTable Options).
A46: 7. DATA QUALITY CHECKS (live formulas)
A47: Record count = 500 | B47: Number of serial numbers on Sales Data | C47: =IF(COUNT('Sales Data'!A2:A501)=500,"OK","CHECK") -> OK
...
